Workbook

Sheet Tổng hợp
A1: TỔNG HỢP KẾT QUẢ KIỂM THỬ
A3: STT | B3: Tên màn hình/chức năng | C3: Manual test
C4: Số trường hợp kiểm thử đạt (P) | D4: Số trường hợp kiểm thử không đạt (F) | E4: Số trường hợp kiểm thử đang xem xét (PE) | F4: Số trường hợp kiểm thử chưa thực hiện | G4: Tổng số trường hợp kiểm thử | H4: Tỉ lệ trường hợp kiểm thử đạt (%P) | I4: Tỉ lệ trường hợp kiểm thử không đạt (%F) | J4: Tỉ lệ trường hợp kiểm thử đã thực hiện (%Cover)
A5: 1 | B5: Màn hình "Danh sách hồ sơ pháp lý" (FEAT-XLDL-009-01) | C5: =M1_DanhSach!C7 -> 0 | D5: =M1_DanhSach!C8 -> 0 | E5: =M1_DanhSach!C9 -> 0 | F5: =M1_DanhSach!C10 -> 594 | G5: =M1_DanhSach!C11 -> 594 | H5: =IF(G5=0,"",C5/G5) -> 0 | I5: =IF(G5=0,"",D5/G5) -> 0 | J5: =IF(G5=0,"",(C5+D5+E5)/G5) -> 0
A6: 2 | B6: Popup "Xem chi tiết hồ sơ pháp lý tệp D10/D11" (FEAT-XLDL-009-02) | C6: =M2_ChiTiet_D10D11!C7 -> 0 | D6: =M2_ChiTiet_D10D11!C8 -> 0 | E6: =M2_ChiTiet_D10D11!C9 -> 0 | F6: =M2_ChiTiet_D10D11!C10 -> 174 | G6: =M2_ChiTiet_D10D11!C11 -> 174 | H6: =IF(G6=0,"",C6/G6) -> 0 | I6: =IF(G6=0,"",D6/G6) -> 0 | J6: =IF(G6=0,"",(C6+D6+E6)/G6) -> 0
A7: 3 | B7: Popup "Xem chi tiết hồ sơ pháp lý tệp Q11" (FEAT-XLDL-009-03) | C7: =M3_ChiTiet_Q11!C7 -> 0 | D7: =M3_ChiTiet_Q11!C8 -> 0 | E7: =M3_ChiTiet_Q11!C9 -> 0 | F7: =M3_ChiTiet_Q11!C10 -> 138 | G7: =M3_ChiTiet_Q11!C11 -> 138 | H7: =IF(G7=0,"",C7/G7) -> 0 | I7: =IF(G7=0,"",D7/G7) -> 0 | J7: =IF(G7=0,"",(C7+D7+E7)/G7) -> 0
A8: 4 | B8: Popup "Xử lý hồ sơ pháp lý tệp D10/D11" + popup "Xác nhận cập nhật thông tin hồ sơ"/popup "Xác nhận từ chối cập nhật thông tin hồ sơ" (FEAT-XLDL-009-04) | C8: =M4_XuLy_D10D11!C7 -> 0 | D8: =M4_XuLy_D10D11!C8 -> 0 | E8: =M4_XuLy_D10D11!C9 -> 0 | F8: =M4_XuLy_D10D11!C10 -> 255 | G8: =M4_XuLy_D10D11!C11 -> 255 | H8: =IF(G8=0,"",C8/G8) -> 0 | I8: =IF(G8=0,"",D8/G8) -> 0 | J8: =IF(G8=0,"",(C8+D8+E8)/G8) -> 0
A9: 5 | B9: Popup "Xử lý hồ sơ pháp lý tệp Q11" + popup "Xác nhận cập nhật thông tin hồ sơ"/popup "Xác nhận từ chối cập nhật thông tin hồ sơ" (FEAT-XLDL-009-05) | C9: =M5_XuLy_Q11!C7 -> 0 | D9: =M5_XuLy_Q11!C8 -> 0 | E9: =M5_XuLy_Q11!C9 -> 0 | F9: =M5_XuLy_Q11!C10 -> 243 | G9: =M5_XuLy_Q11!C11 -> 243 | H9: =IF(G9=0,"",C9/G9) -> 0 | I9: =IF(G9=0,"",D9/G9) -> 0 | J9: =IF(G9=0,"",(C9+D9+E9)/G9) -> 0
A10: 6 | B10: Màn hình "Xử lý đồng thời hồ sơ pháp lý" D10/D11 và Q11 + popup "Xác nhận cập nhật thông tin hồ sơ"/popup "Xác nhận từ chối cập nhật thông tin hồ sơ" (FEAT-XLDL-009-06, 07) | C10: =M7_XuLyDongThoi!C7 -> 0 | D10: =M7_XuLyDongThoi!C8 -> 0 | E10: =M7_XuLyDongThoi!C9 -> 0 | F10: =M7_XuLyDongThoi!C10 -> 284 | G10: =M7_XuLyDongThoi!C11 -> 284 | H10: =IF(G10=0,"",C10/G10) -> 0 | I10: =IF(G10=0,"",D10/G10) -> 0 | J10: =IF(G10=0,"",(C10+D10+E10)/G10) -> 0
A11: 7 | B11: Xử lý tự động khi tiếp nhận, trạng thái và tích hợp (FEAT-XLDL-009-08) | C11: =M8_NghiepVu_TichHop!C7 -> 0 | D11: =M8_NghiepVu_TichHop!C8 -> 0 | E11: =M8_NghiepVu_TichHop!C9 -> 0 | F11: =M8_NghiepVu_TichHop!C10 -> 33 | G11: =M8_NghiepVu_TichHop!C11 -> 33 | H11: =IF(G11=0,"",C11/G11) -> 0 | I11: =IF(G11=0,"",D11/G11) -> 0 | J11: =IF(G11=0,"",(C11+D11+E11)/G11) -> 0
A12: Total | C12: =SUM(C5:C11) -> 0 | D12: =SUM(D5:D11) -> 0 | E12: =SUM(E5:E11) -> 0 | F12: =SUM(F5:F11) -> 1721 | G12: =SUM(G5:G11) -> 1721 | H12: =IF(G12=0,"",C12/G12) -> 0 | I12: =IF(G12=0,"",D12/G12) -> 0 | J12: =IF(G12=0,"",(C12+D12+E12)/G12) -> 0

Sheet M1_DanhSach
B1: KỊCH BẢN KIỂM THỬ CHỨC NĂNG
B3: Tên màn hình/Tên chức năng | C3: Màn hình "Danh sách hồ sơ pháp lý" (FEAT-XLDL-009-01) | E3: KBNV
B4: Mã trường hợp kiểm thử | C4: HSPL | E4: TKCT
B6: Manual test
B7: Số trường hợp kiểm thử đạt (P) | C7: =COUNTIF($O$20:$O$677,"P") -> 0
B8: Số trường hợp kiểm thử không đạt (F) | C8: =COUNTIF($O$20:$O$677,"F") -> 0
B9: Số trường hợp kiểm thử đang xem xét (PE) | C9: =COUNTIF($O$20:$O$677,"PE") -> 0
B10: Số trường hợp kiểm thử chưa thực hiện | C10: =C11-C7-C8-C9 -> 594
B11: Tổng số trường hợp kiểm thử | C11: =COUNTA($F$20:$F$677) -> 594
A15: ID | B15: Mục đích kiểm thử | C15: Trường hợp kiểm thử | D15: Data test | E15: Các bước thực hiện | F15: Kết quả mong muốn | G15: Mức độ nghiêm trọng | H15: Hình ảnh | I15: Manual Test | O15: Kết quả test (M) | P15: Mã lỗi | Q15: Ghi chú
I16: WEB
I17: Lần 1 | J17: Ngày thực hiện | K17: Lần 2 | L17: Ngày thực hiện | M17: Lần 3 | N17: Ngày thực hiện
B18: Pre-condition: - Đăng nhập tài khoản cbxl01 (ROLE-CBTTXLDL, phân quyền TCTD 31358001 và 79202501) - Menu: Thu thập và xử lý dữ liệu > Xử lý dữ liệu > Hồ sơ pháp lý - Kho tiền dữ liệu có hồ sơ pháp lý hợp lệ tệp D10, D11, Q11 của cả KH Cá nhân và Tổ chức, ở đủ 4 trạng thái Chờ cấp mã / Chờ xem xét / Đã xử lý / Từ chối - Đầu mối 31358001 có > 1.000 hồ sơ tệp D11 (đủ để phân trang tới trang 50) - Đầu mối 01201001 là đầu mối gửi báo cáo nhưng KHÔNG thuộc TCTD được phân quyền của cbxl01
B19: Giao diện (Phần này viết các trường hợp kiểm thử cho giao diện chung và các giao diện cho các control)
A20: =IF(F20="","",ROW()-19-COUNTBLANK($F$20:F20)) | B20: Kiểm tra giao diện chung
A21: =IF(F21="","",ROW()-19-COUNTBLANK($F$20:F21)) -> 1 | B21: Kiểm tra hiển thị màn hình mặc định | C21: Hiển thị màn hình "Danh sách hồ sơ pháp lý" khi mở | E21: 1. Mở màn hình "Danh sách hồ sơ pháp lý" 2. Quan sát màn hình "Danh sách hồ sơ pháp lý" | F21: Hiển thị đúng như SRS: - Tiêu đề "Danh sách hồ sơ pháp lý", breadcrumb Trang chủ / Xử lý dữ liệu - Nút Cấu hình hiển thị, Xuất Excel - Điều kiện: Loại khách hàng (*) = Cá nhân, Mã đầu mối (*) trống, Mã tệp (*) = tệp đầu tiên được phân quyền (D10), Mã CIC, Mã khách hàng, Nhóm khách hàng, Trạng thái, Người cập nhật, Từ ngày cập nhật → Đến ngày cập nhật, Từ ngày báo cáo → Đến ngày báo cáo; Tên tệp và CCCD/CMND KHÔNG hiển thị (mặc định tắt) - Nút Thêm bộ lọc, Làm mới, Tìm kiếm - Lưới: checkbox, STT, Ngày báo cáo, Mã đầu mối, Mã khách hàng, Tên khách hàng, CCCD, Địa chỉ, Mã CIC, Nhóm khách hàng, Trạng thái, Thao tác (Mã tệp, Tên tệp, Loại khách hàng, Ngày cập nhật, Người cập nhật ẩn) - Vùng lưới hiển thị "Chưa có dữ liệu. Vui lòng chọn tiêu chí tìm kiếm."; phân trang 20 / trang - Không hiển thị dải thao tác hàng loạt và banner INF_009 (BR-013, BR-019, BR-021) | G21: Cao
A22: =IF(F22="","",ROW()-19-COUNTBLANK($F$20:F22)) -> 2 | B22: Kiểm tra tổng thể giao diện màn hình | C22: Bố cục, font chữ, căn lề, dấu (*), chính tả | E22: 1. Mở màn hình "Danh sách hồ sơ pháp lý" 2. Quan sát toàn bộ label, control, button | F22: 1. Label, control có kích thước, khoảng cách đồng đều, không xô lệch 2. Cùng một font, cỡ chữ; label căn trái 3. Trường bắt buộc có dấu (*) 4. Không có lỗi chính tả, ngữ pháp | G22: Trung bình
A23: =IF(F23="","",ROW()-19-COUNTBLANK($F$20:F23)) -> 3 | B23: Kiểm tra thứ tự di chuyển con trỏ khi nhấn phím Tab | C23: Nhấn Tab liên tục từ control đầu tiên | E23: 1. Mở màn hình "Danh sách hồ sơ pháp lý" 2. Nhấn phím Tab liên tục | F23: Con trỏ di chuyển lần lượt: Cấu hình hiển thị → Xuất Excel → Loại khách hàng → Mã đầu mối → Mã tệp → Mã CIC → Mã khách hàng → Nhóm khách hàng → Trạng thái → Người cập nhật → Từ ngày cập nhật → Đến ngày cập nhật → Từ ngày báo cáo → Đến ngày báo cáo → Thêm bộ lọc → Làm mới → Tìm kiếm → lưới → phân trang | G23: Trung bình
A24: =IF(F24="","",ROW()-19-COUNTBLANK($F$20:F24)) -> 4 | B24: Kiểm tra thứ tự di chuyển con trỏ khi nhấn phím Shift+Tab | C24: Nhấn Shift+Tab liên tục từ control cuối cùng | E24: 1. Mở màn hình "Danh sách hồ sơ pháp lý" 2. Focus control cuối cùng 3. Nhấn Shift+Tab liên tục | F24: Con trỏ di chuyển theo thứ tự ngược lại với phím Tab (từ dưới lên trên, từ phải sang trái) | G24: Trung bình
A25: =IF(F25="","",ROW()-19-COUNTBLANK($F$20:F25)) -> 5 | B25: Kiểm tra phím Enter | C25: Nhấn Enter khi đang focus control | E25: 1. Mở màn hình "Danh sách hồ sơ pháp lý" 2. Focus control 3. Nhấn phím Enter | F25: Focus ô điều kiện và nhấn Enter → kích hoạt Tìm kiếm; focus nút → thực hiện chức năng của nút | G25: Trung bình
A26: =IF(F26="","",ROW()-19-COUNTBLANK($F$20:F26)) -> 6 | B26: Kiểm tra tính năng responsive màn hình | C26: Thay đổi mức zoom bằng Ctrl+− / Ctrl+= | D26: Zoom 75%, 100%, 125%, 150% | E26: 1. Mở màn hình "Danh sách hồ sơ pháp lý" 2. Nhấn Ctrl+− / Ctrl+= để đổi mức zoom | F26: Layout hiển thị hài hòa, không tràn khung, không vỡ giao diện ở mọi mức zoom | G26: Thấp
A27: =IF(F27="","",ROW()-19-COUNTBLANK($F$20:F27)) -> 7 | B27: Kiểm tra ngôn ngữ tiếng Việt chuẩn hành chính | C27: Rà toàn bộ nhãn, từ viết tắt trên màn hình | D27: Từ viết tắt: KH, TCTD, TTQT, QHTD, CIC, C06 | E27: 1. Mở màn hình "Danh sách hồ sơ pháp lý" 2. Rà các nhãn, giá trị có từ viết tắt | F27: Không có từ viết tắt không được định nghĩa; từ viết tắt có tooltip giải thích (Quy tắc component) | G27: Thấp
A28: =IF(F28="","",ROW()-19-COUNTBLANK($F$20:F28)) -> 8 | B28: Kiểm tra phím tắt thao tác | C28: Phím tắt theo Quy tắc component | D28: F5; Ctrl+Shift+E; Ctrl+P | E28: 1. Mở màn hình "Danh sách hồ sơ pháp lý", chọn Loại KH = Cá nhân, Mã đầu mối = 31358001, Mã tệp = D11, click Tìm kiếm 2. Nhấn lần lượt F5, Ctrl+Shift+E, Ctrl+P | F28: F5 làm mới trang; Ctrl+Shift+E mở lựa chọn Xuất Excel; Ctrl+P mở In trang hiện tại | G28: Thấp
A29: =IF(F29="","",ROW()-19-COUNTBLANK($F$20:F29)) | B29: Kiểm tra title Danh sách hồ sơ pháp lý
A30: =IF(F30="","",ROW()-19-COUNTBLANK($F$20:F30)) -> 9 | B30: Kiểm tra hiển thị title | C30: Kiểm tra hiển thị title | E30: 1. Mở màn hình "Danh sách hồ sơ pháp lý" 2. Kiểm tra hiển thị title | F30: Title cố định mặc định: "Danh sách hồ sơ pháp lý" | G30: Thấp
A31: =IF(F31="","",ROW()-19-COUNTBLANK($F$20:F31)) -> 10 | B31: Kiểm tra chỉnh sửa title | C31: Kiểm tra chỉnh sửa title | E31: 1. Mở màn hình "Danh sách hồ sơ pháp lý" 2. Click / thử nhập vào title | F31: Không cho phép chỉnh sửa | G31: Thấp
A32: =IF(F32="","",ROW()-19-COUNTBLANK($F$20:F32)) | B32: Kiểm tra button chung trên màn hình
A33: =IF(F33="","",ROW()-19-COUNTBLANK($F$20:F33)) -> 11 | B33: Kiểm tra căn lề, chính tả label button | C33: Kiểm tra căn lề, chính tả label các button | E33: 1. Mở màn hình "Danh sách hồ sơ pháp lý" 2. Quan sát các button: Cấu hình hiển thị, Xuất Excel, Thêm bộ lọc, Làm mới, Tìm kiếm, Xử lý hồ sơ, Bỏ chọn | F33: Text căn giữa, chữ thường và chữ cái đầu in hoa, không lỗi chính tả | G33: Thấp
A34: =IF(F34="","",ROW()-19-COUNTBLANK($F$20:F34)) -> 12 | B34: Kiểm tra trạng thái enabled/disabled của các button theo điều kiện | C34: Kiểm tra trạng thái các button | E34: 1. Mở màn hình "Danh sách hồ sơ pháp lý" 2. Quan sát trạng thái các button | F34: Hiển thị đúng trạng thái theo điều kiện SRS; chỉ có duy nhất 1 Primary button (Tìm kiếm) trong một khu vực | G34: Trung bình
A35: =IF(F35="","",ROW()-19-COUNTBLANK($F$20:F35)) -> 13 | B35: Kiểm tra click button thực hiện đúng chức năng | C35: Kiểm tra click các button | E35: 1. Mở màn hình "Danh sách hồ sơ pháp lý" 2. Click lần lượt từng button | F35: Mỗi button thực hiện đúng chức năng mô tả trong SRS | G35: Cao
A36: =IF(F36="","",ROW()-19-COUNTBLANK($F$20:F36)) -> 14 | B36: Kiểm tra loading và disable button khi đang xử lý | C36: Kiểm tra button khi hệ thống đang xử lý | D36: Giả lập mạng chậm (DevTools: Slow 3G) | E36: 1. Mở màn hình "Danh sách hồ sơ pháp lý" 2. Click button gọi API 3. Click tiếp nhiều lần khi đang xử lý | F36: Button hiển thị loading spinner và bị disable; thao tác chỉ được thực hiện 1 lần | G36: Cao
A37: =IF(F37="","",ROW()-19-COUNTBLANK($F$20:F37)) -> 15 | B37: Kiểm tra giữ bộ lọc sau khi F5 hoặc chuyển trang | C37: Kiểm tra giữ tùy chọn bộ lọc và cấu hình hiển thị | E37: 1. Mở màn hình "Danh sách hồ sơ pháp lý" 2. Chọn điều kiện, Tìm kiếm 3. Nhấn F5 hoặc chuyển sang chức năng khác rồi quay lại | F37: Hệ thống giữ tùy chọn bộ lọc và cấu hình hiển thị đã chọn trước đó (không lưu giá trị) — Quy tắc component | G37: Trung bình
A38: =IF(F38="","",ROW()-19-COUNTBLANK($F$20:F38)) | B38: Kiểm tra button Cấu hình hiển thị
A39: =IF(F39="","",ROW()-19-COUNTBLANK($F$20:F39)) -> 16 | B39: Kiểm tra hiển thị button | C39: Kiểm tra hiển thị nút Cấu hình hiển thị | E39: 1. Mở màn hình "Danh sách hồ sơ pháp lý" 2. Quan sát nút Cấu hình hiển thị | F39: Button hiển thị giống như trong SRS: góc phải tiêu đề trang, có icon, nhãn "Cấu hình hiển thị" | G39: Trung bình
A40: =IF(F40="","",ROW()-19-COUNTBLANK($F$20:F40)) -> 17 | B40: Kiểm tra trạng thái button | C40: Kiểm tra trạng thái enable/disable của nút Cấu hình hiển thị | E40: 1. Mở màn hình "Danh sách hồ sơ pháp lý" 2. Quan sát trạng thái nút Cấu hình hiển thị theo từng điều kiện | F40: Trạng thái: Enable | G40: Trung bình
A41: =IF(F41="","",ROW()-19-COUNTBLANK($F$20:F41)) -> 18 | B41: Kiểm tra thao tác click button | C41: Kiểm tra click nút Cấu hình hiển thị | E41: 1. Mở màn hình "Danh sách hồ sơ pháp lý" 2. Click nút Cấu hình hiển thị | F41: Hiển thị popup Cấu hình hiển thị gồm: tiêu đề "Cấu hình hiển thị", icon X, ô tìm kiếm trường thông tin, danh sách cột kèm checkbox theo đúng thứ tự trên lưới: - STT: mặc định check - Ngày báo cáo: mặc định check (disable) - Mã tệp: mặc định uncheck - Tên tệp: mặc định uncheck - Mã đầu mối: mặc định check (disable) - Mã khách hàng: mặc định check (disable) - Tên khách hàng: mặc định check - CCCD/MSDN: mặc định check - Địa chỉ: mặc định check - Loại khách hàng: mặc định uncheck - Mã CIC: mặc định check - Nhóm khách hàng: mặc định check - Trạng thái: mặc định check - Ngày cập nhật: mặc định uncheck - Người cập nhật: mặc định uncheck - Thao tác: mặc định check (disable) - Button Bỏ chọn, Chọn tất cả, Áp dụng (BR-021, CMP-025) | G41: Trung bình
A42: =IF(F42="","",ROW()-19-COUNTBLANK($F$20:F42)) | B42: Kiểm tra title popup Cấu hình hiển thị
A43: =IF(F43="","",ROW()-19-COUNTBLANK($F$20:F43)) -> 19 | B43: Kiểm tra hiển thị title | C43: Kiểm tra hiển thị title | E43: 1. Mở màn hình "Danh sách hồ sơ pháp lý", chọn Loại KH = Cá nhân, Mã đầu mối = 31358001, Mã tệp = D11, click Tìm kiếm, click button Cấu hình hiển thị 2. Kiểm tra hiển thị title | F43: Title cố định: "Cấu hình hiển thị" | G43: Thấp
A44: =IF(F44="","",ROW()-19-COUNTBLANK($F$20:F44)) -> 20 | B44: Kiểm tra chỉnh sửa title | C44: Kiểm tra chỉnh sửa title | E44: 1. Mở màn hình "Danh sách hồ sơ pháp lý", chọn Loại KH = Cá nhân, Mã đầu mối = 31358001, Mã tệp = D11, click Tìm kiếm, click button Cấu hình hiển thị 2. Click vào title | F44: Không được chỉnh sửa | G44: Thấp
A45: =IF(F45="","",ROW()-19-COUNTBLANK($F$20:F45)) | B45: Kiểm tra ô tìm kiếm trường thông tin trên popup Cấu hình hiển thị
...

Sheet M2_ChiTiet_D10D11
B1: KỊCH BẢN KIỂM THỬ CHỨC NĂNG
B3: Tên màn hình/Tên chức năng | C3: Popup "Xem chi tiết hồ sơ pháp lý tệp D10/D11" (FEAT-XLDL-009-02) | E3: KBNV
B4: Mã trường hợp kiểm thử | C4: HSPL | E4: TKCT
B6: Manual test
B7: Số trường hợp kiểm thử đạt (P) | C7: =COUNTIF($O$20:$O$218,"P") -> 0
B8: Số trường hợp kiểm thử không đạt (F) | C8: =COUNTIF($O$20:$O$218,"F") -> 0
B9: Số trường hợp kiểm thử đang xem xét (PE) | C9: =COUNTIF($O$20:$O$218,"PE") -> 0
B10: Số trường hợp kiểm thử chưa thực hiện | C10: =C11-C7-C8-C9 -> 174
B11: Tổng số trường hợp kiểm thử | C11: =COUNTA($F$20:$F$218) -> 174
A15: ID | B15: Mục đích kiểm thử | C15: Trường hợp kiểm thử | D15: Data test | E15: Các bước thực hiện | F15: Kết quả mong muốn | G15: Mức độ nghiêm trọng | H15: Hình ảnh | I15: Manual Test | O15: Kết quả test (M) | P15: Mã lỗi | Q15: Ghi chú
I16: WEB
I17: Lần 1 | J17: Ngày thực hiện | K17: Lần 2 | L17: Ngày thực hiện | M17: Lần 3 | N17: Ngày thực hiện
B18: Pre-condition: - Đăng nhập tài khoản cbxl01 (ROLE-CBTTXLDL, phân quyền TCTD 31358001 và 79202501) - Menu: Thu thập và xử lý dữ liệu > Xử lý dữ liệu > Hồ sơ pháp lý - Kho tiền dữ liệu có hồ sơ pháp lý hợp lệ tệp D10, D11, Q11 của cả KH Cá nhân và Tổ chức, ở đủ 4 trạng thái Chờ cấp mã / Chờ xem xét / Đã xử lý / Từ chối
B19: Giao diện (Phần này viết các trường hợp kiểm thử cho giao diện chung và các giao diện cho các control)
A20: =IF(F20="","",ROW()-19-COUNTBLANK($F$20:F20)) | B20: Kiểm tra giao diện chung
A21: =IF(F21="","",ROW()-19-COUNTBLANK($F$20:F21)) -> 1 | B21: Kiểm tra hiển thị màn hình mặc định | C21: Hiển thị popup "Xem chi tiết hồ sơ pháp lý tệp D10/D11" khi mở | E21: 1. Tại màn hình "Danh sách hồ sơ pháp lý" (Cá nhân, 31358001, D11) mở menu Thao tác → Xem của hồ sơ cá nhân 2. Quan sát popup "Xem chi tiết hồ sơ pháp lý tệp D10/D11" | F21: Popup "Xem chi tiết hồ sơ pháp lý tệp D10/D11" hiển thị: - 2 tab: Thông tin hồ sơ (đang chọn), Lịch sử cập nhật - Thẻ: Tên khách hàng, Đầu mối báo cáo, Mã khách hàng, Loại khách hàng, Nhóm khách hàng, Mã CIC, Trạng thái (badge), Lý do (khi Đã xử lý/Từ chối), Tên tệp - Nhóm Thông tin khai báo chung: KB001, KB002, KB003, KB004 - Các nhóm chỉ tiêu theo Loại khách hàng - Nút Đóng | G21: Cao
A22: =IF(F22="","",ROW()-19-COUNTBLANK($F$20:F22)) -> 2 | B22: Kiểm tra tổng thể giao diện màn hình | C22: Bố cục, font chữ, căn lề, dấu (*), chính tả | E22: 1. Tại màn hình "Danh sách hồ sơ pháp lý" (Cá nhân, 31358001, D11) mở menu Thao tác → Xem của hồ sơ cá nhân 2. Quan sát toàn bộ label, control, button | F22: 1. Label, control có kích thước, khoảng cách đồng đều, không xô lệch 2. Cùng một font, cỡ chữ; label căn trái 3. Trường bắt buộc có dấu (*) 4. Không có lỗi chính tả, ngữ pháp | G22: Trung bình
A23: =IF(F23="","",ROW()-19-COUNTBLANK($F$20:F23)) -> 3 | B23: Kiểm tra thứ tự di chuyển con trỏ khi nhấn phím Tab | C23: Nhấn Tab liên tục từ control đầu tiên | E23: 1. Tại màn hình "Danh sách hồ sơ pháp lý" (Cá nhân, 31358001, D11) mở menu Thao tác → Xem của hồ sơ cá nhân 2. Nhấn phím Tab liên tục | F23: Con trỏ di chuyển lần lượt: Tab Thông tin hồ sơ → Tab Lịch sử cập nhật → vùng nội dung → nút Đóng | G23: Trung bình
A24: =IF(F24="","",ROW()-19-COUNTBLANK($F$20:F24)) -> 4 | B24: Kiểm tra thứ tự di chuyển con trỏ khi nhấn phím Shift+Tab | C24: Nhấn Shift+Tab liên tục từ control cuối cùng | E24: 1. Tại màn hình "Danh sách hồ sơ pháp lý" (Cá nhân, 31358001, D11) mở menu Thao tác → Xem của hồ sơ cá nhân 2. Focus control cuối cùng 3. Nhấn Shift+Tab liên tục | F24: Con trỏ di chuyển theo thứ tự ngược lại với phím Tab (từ dưới lên trên, từ phải sang trái) | G24: Trung bình
A25: =IF(F25="","",ROW()-19-COUNTBLANK($F$20:F25)) -> 5 | B25: Kiểm tra phím Enter | C25: Nhấn Enter khi đang focus control | E25: 1. Tại màn hình "Danh sách hồ sơ pháp lý" (Cá nhân, 31358001, D11) mở menu Thao tác → Xem của hồ sơ cá nhân 2. Focus control 3. Nhấn phím Enter | F25: Focus nút Đóng và nhấn Enter → đóng popup; focus tab và nhấn Enter → chuyển tab | G25: Trung bình
A26: =IF(F26="","",ROW()-19-COUNTBLANK($F$20:F26)) -> 6 | B26: Kiểm tra tính năng responsive màn hình | C26: Thay đổi mức zoom bằng Ctrl+− / Ctrl+= | D26: Zoom 75%, 100%, 125%, 150% | E26: 1. Tại màn hình "Danh sách hồ sơ pháp lý" (Cá nhân, 31358001, D11) mở menu Thao tác → Xem của hồ sơ cá nhân 2. Nhấn Ctrl+− / Ctrl+= để đổi mức zoom | F26: Layout hiển thị hài hòa, không tràn khung, không vỡ giao diện ở mọi mức zoom | G26: Thấp
A27: =IF(F27="","",ROW()-19-COUNTBLANK($F$20:F27)) -> 7 | B27: Kiểm tra ngôn ngữ tiếng Việt chuẩn hành chính | C27: Rà toàn bộ nhãn, từ viết tắt trên màn hình | D27: Từ viết tắt: KH, TCTD, TTQT, QHTD, CIC, C06 | E27: 1. Tại màn hình "Danh sách hồ sơ pháp lý" (Cá nhân, 31358001, D11) mở menu Thao tác → Xem của hồ sơ cá nhân 2. Rà các nhãn, giá trị có từ viết tắt | F27: Không có từ viết tắt không được định nghĩa; từ viết tắt có tooltip giải thích (Quy tắc component) | G27: Thấp
A28: =IF(F28="","",ROW()-19-COUNTBLANK($F$20:F28)) | B28: Kiểm tra title Xem chi tiết hồ sơ pháp lý
A29: =IF(F29="","",ROW()-19-COUNTBLANK($F$20:F29)) -> 8 | B29: Kiểm tra hiển thị title | C29: Kiểm tra hiển thị title | E29: 1. Tại màn hình "Danh sách hồ sơ pháp lý" (Cá nhân, 31358001, D11) mở menu Thao tác → Xem của hồ sơ cá nhân 2. Kiểm tra hiển thị title | F29: Title cố định mặc định: "Xem chi tiết hồ sơ pháp lý" | G29: Thấp
A30: =IF(F30="","",ROW()-19-COUNTBLANK($F$20:F30)) -> 9 | B30: Kiểm tra chỉnh sửa title | C30: Kiểm tra chỉnh sửa title | E30: 1. Tại màn hình "Danh sách hồ sơ pháp lý" (Cá nhân, 31358001, D11) mở menu Thao tác → Xem của hồ sơ cá nhân 2. Click / thử nhập vào title | F30: Không cho phép chỉnh sửa | G30: Thấp
A31: =IF(F31="","",ROW()-19-COUNTBLANK($F$20:F31)) | B31: Kiểm tra Tabs
A32: =IF(F32="","",ROW()-19-COUNTBLANK($F$20:F32)) -> 10 | B32: Kiểm tra tab mặc định | C32: Tab mở sẵn khi vào màn | E32: 1. Tại màn hình "Danh sách hồ sơ pháp lý" (Cá nhân, 31358001, D11) mở menu Thao tác → Xem của hồ sơ cá nhân | F32: Tab Thông tin hồ sơ được chọn mặc định (BR-028, AC#1) | G32: Cao
A33: =IF(F33="","",ROW()-19-COUNTBLANK($F$20:F33)) -> 11 | B33: Kiểm tra chuyển sang tab lịch sử cập nhật | C33: Click tab Lịch sử cập nhật | E33: 1. Tại màn hình "Danh sách hồ sơ pháp lý" (Cá nhân, 31358001, D11) mở menu Thao tác → Xem của hồ sơ cá nhân 2. Click tab Lịch sử cập nhật | F33: Hiển thị bảng lịch sử của khách hàng; tab được highlight | G33: Cao
A34: =IF(F34="","",ROW()-19-COUNTBLANK($F$20:F34)) -> 12 | B34: Kiểm tra quay lại tab thông tin hồ sơ | C34: Click lại tab Thông tin hồ sơ | E34: 1. Tại màn hình "Danh sách hồ sơ pháp lý" (Cá nhân, 31358001, D11) mở menu Thao tác → Xem của hồ sơ cá nhân, chọn tab Lịch sử cập nhật 2. Click tab Thông tin hồ sơ | F34: Hiển thị lại thông tin hồ sơ, không tải lại popup (ALT-01) | G34: Trung bình
A35: =IF(F35="","",ROW()-19-COUNTBLANK($F$20:F35)) -> 13 | B35: Kiểm tra chuyển tab bằng bàn phím | C35: Ctrl+Tab / Ctrl+Shift+Tab | E35: 1. Tại màn hình "Danh sách hồ sơ pháp lý" (Cá nhân, 31358001, D11) mở menu Thao tác → Xem của hồ sơ cá nhân 2. Nhấn Ctrl+Tab 3. Nhấn Ctrl+Shift+Tab | F35: Chuyển qua lại giữa 2 tab (Quy tắc component) | G35: Thấp
A36: =IF(F36="","",ROW()-19-COUNTBLANK($F$20:F36)) | B36: Kiểm tra thẻ thông tin hồ sơ
A37: =IF(F37="","",ROW()-19-COUNTBLANK($F$20:F37)) -> 14 | B37: Kiểm tra hiển thị trường tên khách hàng | C37: Hiển thị Tên khách hàng | E37: 1. Tại màn hình "Danh sách hồ sơ pháp lý" (Cá nhân, 31358001, D11) mở menu Thao tác → Xem của hồ sơ cá nhân 2. Quan sát Tên khách hàng | F37: Hiển thị nhãn "Tên khách hàng" và giá trị: TTC04; chỉ đọc | G37: Trung bình
A38: =IF(F38="","",ROW()-19-COUNTBLANK($F$20:F38)) -> 15 | B38: Kiểm tra hiển thị trường đầu mối báo cáo | C38: Hiển thị Đầu mối báo cáo | E38: 1. Tại màn hình "Danh sách hồ sơ pháp lý" (Cá nhân, 31358001, D11) mở menu Thao tác → Xem của hồ sơ cá nhân 2. Quan sát Đầu mối báo cáo | F38: Hiển thị nhãn "Đầu mối báo cáo" và giá trị: TTC00, hiển thị mã - tên (assumption Q37); chỉ đọc | G38: Trung bình
A39: =IF(F39="","",ROW()-19-COUNTBLANK($F$20:F39)) -> 16 | B39: Kiểm tra hiển thị trường mã khách hàng | C39: Hiển thị Mã khách hàng | E39: 1. Tại màn hình "Danh sách hồ sơ pháp lý" (Cá nhân, 31358001, D11) mở menu Thao tác → Xem của hồ sơ cá nhân 2. Quan sát Mã khách hàng | F39: Hiển thị nhãn "Mã khách hàng" và giá trị: TTC03; chỉ đọc | G39: Trung bình
A40: =IF(F40="","",ROW()-19-COUNTBLANK($F$20:F40)) -> 17 | B40: Kiểm tra hiển thị trường loại khách hàng | C40: Hiển thị Loại khách hàng | E40: 1. Tại màn hình "Danh sách hồ sơ pháp lý" (Cá nhân, 31358001, D11) mở menu Thao tác → Xem của hồ sơ cá nhân 2. Quan sát Loại khách hàng | F40: Hiển thị nhãn "Loại khách hàng" và giá trị: Cá nhân hoặc Tổ chức; chỉ đọc | G40: Trung bình
A41: =IF(F41="","",ROW()-19-COUNTBLANK($F$20:F41)) -> 18 | B41: Kiểm tra hiển thị trường nhóm khách hàng | C41: Hiển thị Nhóm khách hàng | E41: 1. Tại màn hình "Danh sách hồ sơ pháp lý" (Cá nhân, 31358001, D11) mở menu Thao tác → Xem của hồ sơ cá nhân 2. Quan sát Nhóm khách hàng | F41: Hiển thị nhãn "Nhóm khách hàng" và giá trị: Một trong 4 nhóm (BR-016); chỉ đọc | G41: Trung bình
A42: =IF(F42="","",ROW()-19-COUNTBLANK($F$20:F42)) -> 19 | B42: Kiểm tra hiển thị trường mã cic | C42: Hiển thị Mã CIC | E42: 1. Tại màn hình "Danh sách hồ sơ pháp lý" (Cá nhân, 31358001, D11) mở menu Thao tác → Xem của hồ sơ cá nhân 2. Quan sát Mã CIC | F42: Hiển thị nhãn "Mã CIC" và giá trị: Mã CIC nếu có; trống khi Chờ cấp mã; chỉ đọc | G42: Trung bình
A43: =IF(F43="","",ROW()-19-COUNTBLANK($F$20:F43)) -> 20 | B43: Kiểm tra hiển thị trường tên tệp | C43: Hiển thị Tên tệp | E43: 1. Tại màn hình "Danh sách hồ sơ pháp lý" (Cá nhân, 31358001, D11) mở menu Thao tác → Xem của hồ sơ cá nhân 2. Quan sát Tên tệp | F43: Hiển thị nhãn "Tên tệp" và giá trị: Giá trị đang lưu tại CSDL; chỉ đọc | G43: Trung bình
A44: =IF(F44="","",ROW()-19-COUNTBLANK($F$20:F44)) -> 21 | B44: Kiểm tra hiển thị Lý do theo trạng thái | C44: Hồ sơ Đã xử lý do cán bộ cập nhật | D44: Lý do 'Đã đối chiếu với đơn vị' | E44: 1. Tại màn hình "Danh sách hồ sơ pháp lý" (Cá nhân, 31358001, D11) mở menu Thao tác → Xem của hồ sơ cá nhân | F44: Hiển thị Lý do đang lưu (BR-029) | G44: Cao
A45: =IF(F45="","",ROW()-19-COUNTBLANK($F$20:F45)) -> 22 | C45: Hồ sơ Từ chối | D45: Lý do 'Sai số CCCD' | E45: 1. Tại màn hình "Danh sách hồ sơ pháp lý" (Cá nhân, 31358001, D11) mở menu Thao tác → Xem của hồ sơ cá nhân | F45: Hiển thị Lý do từ chối đang lưu (BR-029) | G45: Cao
...

Sheet M3_ChiTiet_Q11
B1: KỊCH BẢN KIỂM THỬ CHỨC NĂNG
B3: Tên màn hình/Tên chức năng | C3: Popup "Xem chi tiết hồ sơ pháp lý tệp Q11" (FEAT-XLDL-009-03) | E3: KBNV
B4: Mã trường hợp kiểm thử | C4: HSPL | E4: TKCT
B6: Manual test
B7: Số trường hợp kiểm thử đạt (P) | C7: =COUNTIF($O$20:$O$181,"P") -> 0
B8: Số trường hợp kiểm thử không đạt (F) | C8: =COUNTIF($O$20:$O$181,"F") -> 0
B9: Số trường hợp kiểm thử đang xem xét (PE) | C9: =COUNTIF($O$20:$O$181,"PE") -> 0
B10: Số trường hợp kiểm thử chưa thực hiện | C10: =C11-C7-C8-C9 -> 138
B11: Tổng số trường hợp kiểm thử | C11: =COUNTA($F$20:$F$181) -> 138
A15: ID | B15: Mục đích kiểm thử | C15: Trường hợp kiểm thử | D15: Data test | E15: Các bước thực hiện | F15: Kết quả mong muốn | G15: Mức độ nghiêm trọng | H15: Hình ảnh | I15: Manual Test | O15: Kết quả test (M) | P15: Mã lỗi | Q15: Ghi chú
I16: WEB
I17: Lần 1 | J17: Ngày thực hiện | K17: Lần 2 | L17: Ngày thực hiện | M17: Lần 3 | N17: Ngày thực hiện
B18: Pre-condition: - Đăng nhập tài khoản cbxl01 (ROLE-CBTTXLDL, phân quyền TCTD 31358001 và 79202501) - Menu: Thu thập và xử lý dữ liệu > Xử lý dữ liệu > Hồ sơ pháp lý - Kho tiền dữ liệu có hồ sơ pháp lý hợp lệ tệp D10, D11, Q11 của cả KH Cá nhân và Tổ chức, ở đủ 4 trạng thái Chờ cấp mã / Chờ xem xét / Đã xử lý / Từ chối
B19: Giao diện (Phần này viết các trường hợp kiểm thử cho giao diện chung và các giao diện cho các control)
A20: =IF(F20="","",ROW()-19-COUNTBLANK($F$20:F20)) | B20: Kiểm tra giao diện chung
A21: =IF(F21="","",ROW()-19-COUNTBLANK($F$20:F21)) -> 1 | B21: Kiểm tra hiển thị màn hình mặc định | C21: Hiển thị popup "Xem chi tiết hồ sơ pháp lý tệp Q11" khi mở | E21: 1. Tại màn hình "Danh sách hồ sơ pháp lý" (Cá nhân, 31358001, Q11) mở menu Thao tác → Xem của hồ sơ cá nhân 2. Quan sát popup "Xem chi tiết hồ sơ pháp lý tệp Q11" | F21: Popup "Xem chi tiết hồ sơ pháp lý tệp Q11" hiển thị: - 2 tab: Thông tin hồ sơ (đang chọn), Lịch sử cập nhật - Thẻ: Tên khách hàng, Đầu mối báo cáo, Mã khách hàng, Loại khách hàng, Nhóm khách hàng, Mã CIC, Trạng thái (badge), Lý do (khi Đã xử lý/Từ chối), Tên tệp - Nhóm Thông tin khai báo chung: KB001 - Các nhóm chỉ tiêu theo Loại khách hàng - Nút Đóng | G21: Cao
A22: =IF(F22="","",ROW()-19-COUNTBLANK($F$20:F22)) -> 2 | B22: Kiểm tra tổng thể giao diện màn hình | C22: Bố cục, font chữ, căn lề, dấu (*), chính tả | E22: 1. Tại màn hình "Danh sách hồ sơ pháp lý" (Cá nhân, 31358001, Q11) mở menu Thao tác → Xem của hồ sơ cá nhân 2. Quan sát toàn bộ label, control, button | F22: 1. Label, control có kích thước, khoảng cách đồng đều, không xô lệch 2. Cùng một font, cỡ chữ; label căn trái 3. Trường bắt buộc có dấu (*) 4. Không có lỗi chính tả, ngữ pháp | G22: Trung bình
A23: =IF(F23="","",ROW()-19-COUNTBLANK($F$20:F23)) -> 3 | B23: Kiểm tra thứ tự di chuyển con trỏ khi nhấn phím Tab | C23: Nhấn Tab liên tục từ control đầu tiên | E23: 1. Tại màn hình "Danh sách hồ sơ pháp lý" (Cá nhân, 31358001, Q11) mở menu Thao tác → Xem của hồ sơ cá nhân 2. Nhấn phím Tab liên tục | F23: Con trỏ di chuyển lần lượt: Tab Thông tin hồ sơ → Tab Lịch sử cập nhật → vùng nội dung → nút Đóng | G23: Trung bình
A24: =IF(F24="","",ROW()-19-COUNTBLANK($F$20:F24)) -> 4 | B24: Kiểm tra thứ tự di chuyển con trỏ khi nhấn phím Shift+Tab | C24: Nhấn Shift+Tab liên tục từ control cuối cùng | E24: 1. Tại màn hình "Danh sách hồ sơ pháp lý" (Cá nhân, 31358001, Q11) mở menu Thao tác → Xem của hồ sơ cá nhân 2. Focus control cuối cùng 3. Nhấn Shift+Tab liên tục | F24: Con trỏ di chuyển theo thứ tự ngược lại với phím Tab (từ dưới lên trên, từ phải sang trái) | G24: Trung bình
A25: =IF(F25="","",ROW()-19-COUNTBLANK($F$20:F25)) -> 5 | B25: Kiểm tra phím Enter | C25: Nhấn Enter khi đang focus control | E25: 1. Tại màn hình "Danh sách hồ sơ pháp lý" (Cá nhân, 31358001, Q11) mở menu Thao tác → Xem của hồ sơ cá nhân 2. Focus control 3. Nhấn phím Enter | F25: Focus nút Đóng và nhấn Enter → đóng popup; focus tab và nhấn Enter → chuyển tab | G25: Trung bình
A26: =IF(F26="","",ROW()-19-COUNTBLANK($F$20:F26)) -> 6 | B26: Kiểm tra tính năng responsive màn hình | C26: Thay đổi mức zoom bằng Ctrl+− / Ctrl+= | D26: Zoom 75%, 100%, 125%, 150% | E26: 1. Tại màn hình "Danh sách hồ sơ pháp lý" (Cá nhân, 31358001, Q11) mở menu Thao tác → Xem của hồ sơ cá nhân 2. Nhấn Ctrl+− / Ctrl+= để đổi mức zoom | F26: Layout hiển thị hài hòa, không tràn khung, không vỡ giao diện ở mọi mức zoom | G26: Thấp
A27: =IF(F27="","",ROW()-19-COUNTBLANK($F$20:F27)) -> 7 | B27: Kiểm tra ngôn ngữ tiếng Việt chuẩn hành chính | C27: Rà toàn bộ nhãn, từ viết tắt trên màn hình | D27: Từ viết tắt: KH, TCTD, TTQT, QHTD, CIC, C06 | E27: 1. Tại màn hình "Danh sách hồ sơ pháp lý" (Cá nhân, 31358001, Q11) mở menu Thao tác → Xem của hồ sơ cá nhân 2. Rà các nhãn, giá trị có từ viết tắt | F27: Không có từ viết tắt không được định nghĩa; từ viết tắt có tooltip giải thích (Quy tắc component) | G27: Thấp
A28: =IF(F28="","",ROW()-19-COUNTBLANK($F$20:F28)) | B28: Kiểm tra title Xem chi tiết hồ sơ pháp lý
A29: =IF(F29="","",ROW()-19-COUNTBLANK($F$20:F29)) -> 8 | B29: Kiểm tra hiển thị title | C29: Kiểm tra hiển thị title | E29: 1. Tại màn hình "Danh sách hồ sơ pháp lý" (Cá nhân, 31358001, Q11) mở menu Thao tác → Xem của hồ sơ cá nhân 2. Kiểm tra hiển thị title | F29: Title cố định mặc định: "Xem chi tiết hồ sơ pháp lý" | G29: Thấp
A30: =IF(F30="","",ROW()-19-COUNTBLANK($F$20:F30)) -> 9 | B30: Kiểm tra chỉnh sửa title | C30: Kiểm tra chỉnh sửa title | E30: 1. Tại màn hình "Danh sách hồ sơ pháp lý" (Cá nhân, 31358001, Q11) mở menu Thao tác → Xem của hồ sơ cá nhân 2. Click / thử nhập vào title | F30: Không cho phép chỉnh sửa | G30: Thấp
A31: =IF(F31="","",ROW()-19-COUNTBLANK($F$20:F31)) | B31: Kiểm tra Tabs
A32: =IF(F32="","",ROW()-19-COUNTBLANK($F$20:F32)) -> 10 | B32: Kiểm tra tab mặc định | C32: Tab mở sẵn khi vào màn | E32: 1. Tại màn hình "Danh sách hồ sơ pháp lý" (Cá nhân, 31358001, Q11) mở menu Thao tác → Xem của hồ sơ cá nhân | F32: Tab Thông tin hồ sơ được chọn mặc định (BR-028, AC#1) | G32: Cao
A33: =IF(F33="","",ROW()-19-COUNTBLANK($F$20:F33)) -> 11 | B33: Kiểm tra chuyển sang tab lịch sử cập nhật | C33: Click tab Lịch sử cập nhật | E33: 1. Tại màn hình "Danh sách hồ sơ pháp lý" (Cá nhân, 31358001, Q11) mở menu Thao tác → Xem của hồ sơ cá nhân 2. Click tab Lịch sử cập nhật | F33: Hiển thị bảng lịch sử của khách hàng; tab được highlight | G33: Cao
A34: =IF(F34="","",ROW()-19-COUNTBLANK($F$20:F34)) -> 12 | B34: Kiểm tra quay lại tab thông tin hồ sơ | C34: Click lại tab Thông tin hồ sơ | E34: 1. Tại màn hình "Danh sách hồ sơ pháp lý" (Cá nhân, 31358001, Q11) mở menu Thao tác → Xem của hồ sơ cá nhân, chọn tab Lịch sử cập nhật 2. Click tab Thông tin hồ sơ | F34: Hiển thị lại thông tin hồ sơ, không tải lại popup (ALT-01) | G34: Trung bình
A35: =IF(F35="","",ROW()-19-COUNTBLANK($F$20:F35)) -> 13 | B35: Kiểm tra chuyển tab bằng bàn phím | C35: Ctrl+Tab / Ctrl+Shift+Tab | E35: 1. Tại màn hình "Danh sách hồ sơ pháp lý" (Cá nhân, 31358001, Q11) mở menu Thao tác → Xem của hồ sơ cá nhân 2. Nhấn Ctrl+Tab 3. Nhấn Ctrl+Shift+Tab | F35: Chuyển qua lại giữa 2 tab (Quy tắc component) | G35: Thấp
A36: =IF(F36="","",ROW()-19-COUNTBLANK($F$20:F36)) | B36: Kiểm tra thẻ thông tin hồ sơ
A37: =IF(F37="","",ROW()-19-COUNTBLANK($F$20:F37)) -> 14 | B37: Kiểm tra hiển thị trường tên khách hàng | C37: Hiển thị Tên khách hàng | E37: 1. Tại màn hình "Danh sách hồ sơ pháp lý" (Cá nhân, 31358001, Q11) mở menu Thao tác → Xem của hồ sơ cá nhân 2. Quan sát Tên khách hàng | F37: Hiển thị nhãn "Tên khách hàng" và giá trị: TTC04; chỉ đọc | G37: Trung bình
A38: =IF(F38="","",ROW()-19-COUNTBLANK($F$20:F38)) -> 15 | B38: Kiểm tra hiển thị trường đầu mối báo cáo | C38: Hiển thị Đầu mối báo cáo | E38: 1. Tại màn hình "Danh sách hồ sơ pháp lý" (Cá nhân, 31358001, Q11) mở menu Thao tác → Xem của hồ sơ cá nhân 2. Quan sát Đầu mối báo cáo | F38: Hiển thị nhãn "Đầu mối báo cáo" và giá trị: TTC00, hiển thị mã - tên (assumption Q37); chỉ đọc | G38: Trung bình
A39: =IF(F39="","",ROW()-19-COUNTBLANK($F$20:F39)) -> 16 | B39: Kiểm tra hiển thị trường mã khách hàng | C39: Hiển thị Mã khách hàng | E39: 1. Tại màn hình "Danh sách hồ sơ pháp lý" (Cá nhân, 31358001, Q11) mở menu Thao tác → Xem của hồ sơ cá nhân 2. Quan sát Mã khách hàng | F39: Hiển thị nhãn "Mã khách hàng" và giá trị: TTC03; chỉ đọc | G39: Trung bình
A40: =IF(F40="","",ROW()-19-COUNTBLANK($F$20:F40)) -> 17 | B40: Kiểm tra hiển thị trường loại khách hàng | C40: Hiển thị Loại khách hàng | E40: 1. Tại màn hình "Danh sách hồ sơ pháp lý" (Cá nhân, 31358001, Q11) mở menu Thao tác → Xem của hồ sơ cá nhân 2. Quan sát Loại khách hàng | F40: Hiển thị nhãn "Loại khách hàng" và giá trị: Cá nhân hoặc Tổ chức; chỉ đọc | G40: Trung bình
A41: =IF(F41="","",ROW()-19-COUNTBLANK($F$20:F41)) -> 18 | B41: Kiểm tra hiển thị trường nhóm khách hàng | C41: Hiển thị Nhóm khách hàng | E41: 1. Tại màn hình "Danh sách hồ sơ pháp lý" (Cá nhân, 31358001, Q11) mở menu Thao tác → Xem của hồ sơ cá nhân 2. Quan sát Nhóm khách hàng | F41: Hiển thị nhãn "Nhóm khách hàng" và giá trị: Một trong 4 nhóm (BR-016); chỉ đọc | G41: Trung bình
A42: =IF(F42="","",ROW()-19-COUNTBLANK($F$20:F42)) -> 19 | B42: Kiểm tra hiển thị trường mã cic | C42: Hiển thị Mã CIC | E42: 1. Tại màn hình "Danh sách hồ sơ pháp lý" (Cá nhân, 31358001, Q11) mở menu Thao tác → Xem của hồ sơ cá nhân 2. Quan sát Mã CIC | F42: Hiển thị nhãn "Mã CIC" và giá trị: Mã CIC nếu có; trống khi Chờ cấp mã; chỉ đọc | G42: Trung bình
A43: =IF(F43="","",ROW()-19-COUNTBLANK($F$20:F43)) -> 20 | B43: Kiểm tra hiển thị trường tên tệp | C43: Hiển thị Tên tệp | E43: 1. Tại màn hình "Danh sách hồ sơ pháp lý" (Cá nhân, 31358001, Q11) mở menu Thao tác → Xem của hồ sơ cá nhân 2. Quan sát Tên tệp | F43: Hiển thị nhãn "Tên tệp" và giá trị: Giá trị đang lưu tại CSDL; chỉ đọc | G43: Trung bình
A44: =IF(F44="","",ROW()-19-COUNTBLANK($F$20:F44)) -> 21 | B44: Kiểm tra hiển thị Lý do theo trạng thái | C44: Hồ sơ Đã xử lý do cán bộ cập nhật | D44: Lý do 'Đã đối chiếu với đơn vị' | E44: 1. Tại màn hình "Danh sách hồ sơ pháp lý" (Cá nhân, 31358001, Q11) mở menu Thao tác → Xem của hồ sơ cá nhân | F44: Hiển thị Lý do đang lưu (BR-029) | G44: Cao
A45: =IF(F45="","",ROW()-19-COUNTBLANK($F$20:F45)) -> 22 | C45: Hồ sơ Từ chối | D45: Lý do 'Sai số CCCD' | E45: 1. Tại màn hình "Danh sách hồ sơ pháp lý" (Cá nhân, 31358001, Q11) mở menu Thao tác → Xem của hồ sơ cá nhân | F45: Hiển thị Lý do từ chối đang lưu (BR-029) | G45: Cao
...

Sheet M4_XuLy_D10D11
B1: KỊCH BẢN KIỂM THỬ CHỨC NĂNG
B3: Tên màn hình/Tên chức năng | C3: Popup "Xử lý hồ sơ pháp lý tệp D10/D11" + popup "Xác nhận cập nhật thông tin hồ sơ"/popup "Xác nhận từ chối cập nhật thông tin hồ sơ" (FEAT-XLDL-009-04) | E3: KBNV
B4: Mã trường hợp kiểm thử | C4: HSPL | E4: TKCT
B6: Manual test
B7: Số trường hợp kiểm thử đạt (P) | C7: =COUNTIF($O$20:$O$305,"P") -> 0
B8: Số trường hợp kiểm thử không đạt (F) | C8: =COUNTIF($O$20:$O$305,"F") -> 0
B9: Số trường hợp kiểm thử đang xem xét (PE) | C9: =COUNTIF($O$20:$O$305,"PE") -> 0
B10: Số trường hợp kiểm thử chưa thực hiện | C10: =C11-C7-C8-C9 -> 255
B11: Tổng số trường hợp kiểm thử | C11: =COUNTA($F$20:$F$305) -> 255
A15: ID | B15: Mục đích kiểm thử | C15: Trường hợp kiểm thử | D15: Data test | E15: Các bước thực hiện | F15: Kết quả mong muốn | G15: Mức độ nghiêm trọng | H15: Hình ảnh | I15: Manual Test | O15: Kết quả test (M) | P15: Mã lỗi | Q15: Ghi chú
I16: WEB
I17: Lần 1 | J17: Ngày thực hiện | K17: Lần 2 | L17: Ngày thực hiện | M17: Lần 3 | N17: Ngày thực hiện
B18: Pre-condition: - Đăng nhập tài khoản cbxl01 (ROLE-CBTTXLDL, phân quyền TCTD 31358001 và 79202501) - Menu: Thu thập và xử lý dữ liệu > Xử lý dữ liệu > Hồ sơ pháp lý - Kho tiền dữ liệu có hồ sơ pháp lý hợp lệ tệp D10, D11, Q11 của cả KH Cá nhân và Tổ chức, ở đủ 4 trạng thái Chờ cấp mã / Chờ xem xét / Đã xử lý / Từ chối - Có hồ sơ Chờ xem xét của 31358001 có ≥ 3 phiên bản tại kho TCTD cùng Mã CIC và đầu mối; KH có hồ sơ tại CIC (có/không cờ C06) - Danh mục chỉ tiêu đánh dấu quan trọng: TTC04, CN001, CN005, CN006, CN008, CN010, CN016, TC004–TC006, TC011 - Tài khoản cbxl02 (ROLE-CBTTXLDL, phân quyền TCTD 31358001) để kiểm tra xử lý đồng thời giữa 2 cán bộ
B19: Giao diện (Phần này viết các trường hợp kiểm thử cho giao diện chung và các giao diện cho các control)
A20: =IF(F20="","",ROW()-19-COUNTBLANK($F$20:F20)) | B20: Kiểm tra giao diện chung
A21: =IF(F21="","",ROW()-19-COUNTBLANK($F$20:F21)) -> 1 | B21: Kiểm tra hiển thị màn hình mặc định | C21: Hiển thị popup "Xử lý hồ sơ pháp lý tệp D10/D11" khi mở | E21: 1. Tại màn hình "Danh sách hồ sơ pháp lý" (Cá nhân, 31358001, D11) mở menu Thao tác → Xử lý hồ sơ của hồ sơ Chờ xem xét 2. Quan sát popup "Xử lý hồ sơ pháp lý tệp D10/D11" | F21: Popup "Xử lý hồ sơ pháp lý tệp D10/D11" hiển thị: - Thẻ hồ sơ đang xem xét: Tên KH, Mã khách hàng, Loại khách hàng, Đầu mối báo cáo, Ngày báo cáo, Trạng thái - Thẻ Hồ sơ tại CIC: Mã CIC, Loại khách hàng, TCTD có liên quan - Dòng "So sánh thông tin chỉ tiêu": tóm tắt số khác biệt, chú thích ★ / ô tô nền, công tắc "Chỉ hiện chỉ tiêu khác biệt" (tắt) - Bảng 3 cột giá trị: Hồ sơ đang xem xét / Hồ sơ khách hàng tại TCTD (ô chọn Ngày báo cáo) / Hồ sơ khách hàng tại CIC (nhãn C06) - Nút Hủy, Từ chối, Cập nhật | G21: Cao
A22: =IF(F22="","",ROW()-19-COUNTBLANK($F$20:F22)) -> 2 | B22: Kiểm tra tổng thể giao diện màn hình | C22: Bố cục, font chữ, căn lề, dấu (*), chính tả | E22: 1. Tại màn hình "Danh sách hồ sơ pháp lý" (Cá nhân, 31358001, D11) mở menu Thao tác → Xử lý hồ sơ của hồ sơ Chờ xem xét 2. Quan sát toàn bộ label, control, button | F22: 1. Label, control có kích thước, khoảng cách đồng đều, không xô lệch 2. Cùng một font, cỡ chữ; label căn trái 3. Trường bắt buộc có dấu (*) 4. Không có lỗi chính tả, ngữ pháp | G22: Trung bình
A23: =IF(F23="","",ROW()-19-COUNTBLANK($F$20:F23)) -> 3 | B23: Kiểm tra thứ tự di chuyển con trỏ khi nhấn phím Tab | C23: Nhấn Tab liên tục từ control đầu tiên | E23: 1. Tại màn hình "Danh sách hồ sơ pháp lý" (Cá nhân, 31358001, D11) mở menu Thao tác → Xử lý hồ sơ của hồ sơ Chờ xem xét 2. Nhấn phím Tab liên tục | F23: Con trỏ di chuyển lần lượt: công tắc → ô chọn Ngày báo cáo → bảng → Hủy → Từ chối → Cập nhật | G23: Trung bình
A24: =IF(F24="","",ROW()-19-COUNTBLANK($F$20:F24)) -> 4 | B24: Kiểm tra thứ tự di chuyển con trỏ khi nhấn phím Shift+Tab | C24: Nhấn Shift+Tab liên tục từ control cuối cùng | E24: 1. Tại màn hình "Danh sách hồ sơ pháp lý" (Cá nhân, 31358001, D11) mở menu Thao tác → Xử lý hồ sơ của hồ sơ Chờ xem xét 2. Focus control cuối cùng 3. Nhấn Shift+Tab liên tục | F24: Con trỏ di chuyển theo thứ tự ngược lại với phím Tab (từ dưới lên trên, từ phải sang trái) | G24: Trung bình
A25: =IF(F25="","",ROW()-19-COUNTBLANK($F$20:F25)) -> 5 | B25: Kiểm tra phím Enter | C25: Nhấn Enter khi đang focus control | E25: 1. Tại màn hình "Danh sách hồ sơ pháp lý" (Cá nhân, 31358001, D11) mở menu Thao tác → Xử lý hồ sơ của hồ sơ Chờ xem xét 2. Focus control 3. Nhấn phím Enter | F25: Focus nút và nhấn Enter → thực hiện chức năng của nút | G25: Trung bình
A26: =IF(F26="","",ROW()-19-COUNTBLANK($F$20:F26)) -> 6 | B26: Kiểm tra tính năng responsive màn hình | C26: Thay đổi mức zoom bằng Ctrl+− / Ctrl+= | D26: Zoom 75%, 100%, 125%, 150% | E26: 1. Tại màn hình "Danh sách hồ sơ pháp lý" (Cá nhân, 31358001, D11) mở menu Thao tác → Xử lý hồ sơ của hồ sơ Chờ xem xét 2. Nhấn Ctrl+− / Ctrl+= để đổi mức zoom | F26: Layout hiển thị hài hòa, không tràn khung, không vỡ giao diện ở mọi mức zoom | G26: Thấp
A27: =IF(F27="","",ROW()-19-COUNTBLANK($F$20:F27)) -> 7 | B27: Kiểm tra ngôn ngữ tiếng Việt chuẩn hành chính | C27: Rà toàn bộ nhãn, từ viết tắt trên màn hình | D27: Từ viết tắt: KH, TCTD, TTQT, QHTD, CIC, C06 | E27: 1. Tại màn hình "Danh sách hồ sơ pháp lý" (Cá nhân, 31358001, D11) mở menu Thao tác → Xử lý hồ sơ của hồ sơ Chờ xem xét 2. Rà các nhãn, giá trị có từ viết tắt | F27: Không có từ viết tắt không được định nghĩa; từ viết tắt có tooltip giải thích (Quy tắc component) | G27: Thấp
A28: =IF(F28="","",ROW()-19-COUNTBLANK($F$20:F28)) | B28: Kiểm tra button chung trên màn hình
A29: =IF(F29="","",ROW()-19-COUNTBLANK($F$20:F29)) -> 8 | B29: Kiểm tra căn lề, chính tả label button | C29: Kiểm tra căn lề, chính tả label các button | E29: 1. Tại màn hình "Danh sách hồ sơ pháp lý" (Cá nhân, 31358001, D11) mở menu Thao tác → Xử lý hồ sơ của hồ sơ Chờ xem xét 2. Quan sát các button: Hủy, Từ chối, Cập nhật | F29: Text căn giữa, chữ thường và chữ cái đầu in hoa, không lỗi chính tả | G29: Thấp
A30: =IF(F30="","",ROW()-19-COUNTBLANK($F$20:F30)) -> 9 | B30: Kiểm tra trạng thái enabled/disabled của các button theo điều kiện | C30: Kiểm tra trạng thái các button | E30: 1. Tại màn hình "Danh sách hồ sơ pháp lý" (Cá nhân, 31358001, D11) mở menu Thao tác → Xử lý hồ sơ của hồ sơ Chờ xem xét 2. Quan sát trạng thái các button | F30: Hiển thị đúng trạng thái theo điều kiện SRS; chỉ có duy nhất 1 Primary button (Cập nhật) trong một khu vực | G30: Trung bình
A31: =IF(F31="","",ROW()-19-COUNTBLANK($F$20:F31)) -> 10 | B31: Kiểm tra click button thực hiện đúng chức năng | C31: Kiểm tra click các button | E31: 1. Tại màn hình "Danh sách hồ sơ pháp lý" (Cá nhân, 31358001, D11) mở menu Thao tác → Xử lý hồ sơ của hồ sơ Chờ xem xét 2. Click lần lượt từng button | F31: Mỗi button thực hiện đúng chức năng mô tả trong SRS | G31: Cao
A32: =IF(F32="","",ROW()-19-COUNTBLANK($F$20:F32)) -> 11 | B32: Kiểm tra loading và disable button khi đang xử lý | C32: Kiểm tra button khi hệ thống đang xử lý | D32: Giả lập mạng chậm (DevTools: Slow 3G) | E32: 1. Tại màn hình "Danh sách hồ sơ pháp lý" (Cá nhân, 31358001, D11) mở menu Thao tác → Xử lý hồ sơ của hồ sơ Chờ xem xét 2. Click button gọi API 3. Click tiếp nhiều lần khi đang xử lý | F32: Button hiển thị loading spinner và bị disable; thao tác chỉ được thực hiện 1 lần | G32: Cao
A33: =IF(F33="","",ROW()-19-COUNTBLANK($F$20:F33)) -> 12 | B33: Kiểm tra giữ bộ lọc sau khi F5 hoặc chuyển trang | C33: Kiểm tra giữ tùy chọn bộ lọc và cấu hình hiển thị | E33: 1. Tại màn hình "Danh sách hồ sơ pháp lý" (Cá nhân, 31358001, D11) mở menu Thao tác → Xử lý hồ sơ của hồ sơ Chờ xem xét 2. Chọn điều kiện, Tìm kiếm 3. Nhấn F5 hoặc chuyển sang chức năng khác rồi quay lại | F33: Hệ thống giữ tùy chọn bộ lọc và cấu hình hiển thị đã chọn trước đó (không lưu giá trị) — Quy tắc component | G33: Trung bình
A34: =IF(F34="","",ROW()-19-COUNTBLANK($F$20:F34)) | B34: Kiểm tra title Xử lý hồ sơ pháp lý
A35: =IF(F35="","",ROW()-19-COUNTBLANK($F$20:F35)) -> 13 | B35: Kiểm tra hiển thị title | C35: Kiểm tra hiển thị title | E35: 1. Tại màn hình "Danh sách hồ sơ pháp lý" (Cá nhân, 31358001, D11) mở menu Thao tác → Xử lý hồ sơ của hồ sơ Chờ xem xét 2. Kiểm tra hiển thị title | F35: Title cố định mặc định: "Xử lý hồ sơ pháp lý" | G35: Thấp
A36: =IF(F36="","",ROW()-19-COUNTBLANK($F$20:F36)) -> 14 | B36: Kiểm tra chỉnh sửa title | C36: Kiểm tra chỉnh sửa title | E36: 1. Tại màn hình "Danh sách hồ sơ pháp lý" (Cá nhân, 31358001, D11) mở menu Thao tác → Xử lý hồ sơ của hồ sơ Chờ xem xét 2. Click / thử nhập vào title | F36: Không cho phép chỉnh sửa | G36: Thấp
A37: =IF(F37="","",ROW()-19-COUNTBLANK($F$20:F37)) | B37: Kiểm tra thẻ hồ sơ đang xem xét
A38: =IF(F38="","",ROW()-19-COUNTBLANK($F$20:F38)) -> 15 | B38: Kiểm tra hiển thị tên khách hàng | C38: Hiển thị Tên khách hàng | E38: 1. Tại màn hình "Danh sách hồ sơ pháp lý" (Cá nhân, 31358001, D11) mở menu Thao tác → Xử lý hồ sơ của hồ sơ Chờ xem xét 2. Quan sát Tên khách hàng | F38: Hiển thị TTC04 của hồ sơ đang xem xét; chỉ đọc | G38: Trung bình
A39: =IF(F39="","",ROW()-19-COUNTBLANK($F$20:F39)) -> 16 | B39: Kiểm tra hiển thị mã khách hàng | C39: Hiển thị Mã khách hàng | E39: 1. Tại màn hình "Danh sách hồ sơ pháp lý" (Cá nhân, 31358001, D11) mở menu Thao tác → Xử lý hồ sơ của hồ sơ Chờ xem xét 2. Quan sát Mã khách hàng | F39: Hiển thị TTC03, cùng dòng với Mã CIC ở thẻ phải (BR-047); chỉ đọc | G39: Trung bình
A40: =IF(F40="","",ROW()-19-COUNTBLANK($F$20:F40)) -> 17 | B40: Kiểm tra hiển thị loại khách hàng | C40: Hiển thị Loại khách hàng | E40: 1. Tại màn hình "Danh sách hồ sơ pháp lý" (Cá nhân, 31358001, D11) mở menu Thao tác → Xử lý hồ sơ của hồ sơ Chờ xem xét 2. Quan sát Loại khách hàng | F40: Hiển thị TTC05; chỉ đọc | G40: Trung bình
A41: =IF(F41="","",ROW()-19-COUNTBLANK($F$20:F41)) -> 18 | B41: Kiểm tra hiển thị đầu mối báo cáo | C41: Hiển thị Đầu mối báo cáo | E41: 1. Tại màn hình "Danh sách hồ sơ pháp lý" (Cá nhân, 31358001, D11) mở menu Thao tác → Xử lý hồ sơ của hồ sơ Chờ xem xét 2. Quan sát Đầu mối báo cáo | F41: Hiển thị TTC00 dạng mã - tên; chỉ đọc | G41: Trung bình
A42: =IF(F42="","",ROW()-19-COUNTBLANK($F$20:F42)) -> 19 | B42: Kiểm tra hiển thị ngày báo cáo | C42: Hiển thị Ngày báo cáo | E42: 1. Tại màn hình "Danh sách hồ sơ pháp lý" (Cá nhân, 31358001, D11) mở menu Thao tác → Xử lý hồ sơ của hồ sơ Chờ xem xét 2. Quan sát Ngày báo cáo | F42: Hiển thị KB001, DD/MM/YYYY; chỉ đọc | G42: Trung bình
A43: =IF(F43="","",ROW()-19-COUNTBLANK($F$20:F43)) -> 20 | B43: Kiểm tra hiển thị trạng thái | C43: Hiển thị Trạng thái | E43: 1. Tại màn hình "Danh sách hồ sơ pháp lý" (Cá nhân, 31358001, D11) mở menu Thao tác → Xử lý hồ sơ của hồ sơ Chờ xem xét 2. Quan sát Trạng thái | F43: Hiển thị Badge "Chờ xem xét" màu cam; chỉ đọc | G43: Trung bình
A44: =IF(F44="","",ROW()-19-COUNTBLANK($F$20:F44)) | B44: Kiểm tra thẻ Hồ sơ tại CIC
A45: =IF(F45="","",ROW()-19-COUNTBLANK($F$20:F45)) -> 21 | B45: Kiểm tra hiển thị mã CIC | C45: Mã CIC chỉ xem | E45: 1. Tại màn hình "Danh sách hồ sơ pháp lý" (Cá nhân, 31358001, D11) mở menu Thao tác → Xử lý hồ sơ của hồ sơ Chờ xem xét 2. Quan sát Mã CIC 3. Thử click / sửa Mã CIC | F45: Hiển thị Mã CIC của KH, không chọn được mã khác (mục 7 bảng thành phần của popup "Xử lý hồ sơ pháp lý tệp D10/D11") | G45: Cao
...

Sheet M5_XuLy_Q11
B1: KỊCH BẢN KIỂM THỬ CHỨC NĂNG
B3: Tên màn hình/Tên chức năng | C3: Popup "Xử lý hồ sơ pháp lý tệp Q11" + popup "Xác nhận cập nhật thông tin hồ sơ"/popup "Xác nhận từ chối cập nhật thông tin hồ sơ" (FEAT-XLDL-009-05) | E3: KBNV
B4: Mã trường hợp kiểm thử | C4: HSPL | E4: TKCT
B6: Manual test
B7: Số trường hợp kiểm thử đạt (P) | C7: =COUNTIF($O$20:$O$293,"P") -> 0
B8: Số trường hợp kiểm thử không đạt (F) | C8: =COUNTIF($O$20:$O$293,"F") -> 0
B9: Số trường hợp kiểm thử đang xem xét (PE) | C9: =COUNTIF($O$20:$O$293,"PE") -> 0
B10: Số trường hợp kiểm thử chưa thực hiện | C10: =C11-C7-C8-C9 -> 243
B11: Tổng số trường hợp kiểm thử | C11: =COUNTA($F$20:$F$293) -> 243
A15: ID | B15: Mục đích kiểm thử | C15: Trường hợp kiểm thử | D15: Data test | E15: Các bước thực hiện | F15: Kết quả mong muốn | G15: Mức độ nghiêm trọng | H15: Hình ảnh | I15: Manual Test | O15: Kết quả test (M) | P15: Mã lỗi | Q15: Ghi chú
I16: WEB
I17: Lần 1 | J17: Ngày thực hiện | K17: Lần 2 | L17: Ngày thực hiện | M17: Lần 3 | N17: Ngày thực hiện
B18: Pre-condition: - Đăng nhập tài khoản cbxl01 (ROLE-CBTTXLDL, phân quyền TCTD 31358001 và 79202501) - Menu: Thu thập và xử lý dữ liệu > Xử lý dữ liệu > Hồ sơ pháp lý - Kho tiền dữ liệu có hồ sơ pháp lý hợp lệ tệp D10, D11, Q11 của cả KH Cá nhân và Tổ chức, ở đủ 4 trạng thái Chờ cấp mã / Chờ xem xét / Đã xử lý / Từ chối - Có hồ sơ Chờ xem xét của 31358001 có ≥ 3 phiên bản tại kho TCTD cùng Mã CIC và đầu mối; KH có hồ sơ tại CIC (có/không cờ C06) - Danh mục chỉ tiêu đánh dấu quan trọng: TTC04, CN001, CN005, CN006, CN008, CN010, CN016, TC004–TC006, TC011 - Tài khoản cbxl02 (ROLE-CBTTXLDL, phân quyền TCTD 31358001) để kiểm tra xử lý đồng thời giữa 2 cán bộ
B19: Giao diện (Phần này viết các trường hợp kiểm thử cho giao diện chung và các giao diện cho các control)
A20: =IF(F20="","",ROW()-19-COUNTBLANK($F$20:F20)) | B20: Kiểm tra giao diện chung
A21: =IF(F21="","",ROW()-19-COUNTBLANK($F$20:F21)) -> 1 | B21: Kiểm tra hiển thị màn hình mặc định | C21: Hiển thị popup "Xử lý hồ sơ pháp lý tệp Q11" khi mở | E21: 1. Tại màn hình "Danh sách hồ sơ pháp lý" (Cá nhân, 31358001, Q11) mở menu Thao tác → Xử lý hồ sơ của hồ sơ Chờ xem xét 2. Quan sát popup "Xử lý hồ sơ pháp lý tệp Q11" | F21: Popup "Xử lý hồ sơ pháp lý tệp Q11" hiển thị: - Thẻ hồ sơ đang xem xét: Tên KH, Mã khách hàng, Loại khách hàng, Đầu mối báo cáo, Ngày báo cáo, Trạng thái - Thẻ Hồ sơ tại CIC: Mã CIC, Loại khách hàng, TCTD có liên quan - Dòng "So sánh thông tin chỉ tiêu": tóm tắt số khác biệt, chú thích ★ / ô tô nền, công tắc "Chỉ hiện chỉ tiêu khác biệt" (tắt) - Bảng 3 cột giá trị: Hồ sơ đang xem xét / Hồ sơ khách hàng tại TCTD (ô chọn Ngày báo cáo) / Hồ sơ khách hàng tại CIC (nhãn C06) - Nút Hủy, Từ chối, Cập nhật | G21: Cao
A22: =IF(F22="","",ROW()-19-COUNTBLANK($F$20:F22)) -> 2 | B22: Kiểm tra tổng thể giao diện màn hình | C22: Bố cục, font chữ, căn lề, dấu (*), chính tả | E22: 1. Tại màn hình "Danh sách hồ sơ pháp lý" (Cá nhân, 31358001, Q11) mở menu Thao tác → Xử lý hồ sơ của hồ sơ Chờ xem xét 2. Quan sát toàn bộ label, control, button | F22: 1. Label, control có kích thước, khoảng cách đồng đều, không xô lệch 2. Cùng một font, cỡ chữ; label căn trái 3. Trường bắt buộc có dấu (*) 4. Không có lỗi chính tả, ngữ pháp | G22: Trung bình
A23: =IF(F23="","",ROW()-19-COUNTBLANK($F$20:F23)) -> 3 | B23: Kiểm tra thứ tự di chuyển con trỏ khi nhấn phím Tab | C23: Nhấn Tab liên tục từ control đầu tiên | E23: 1. Tại màn hình "Danh sách hồ sơ pháp lý" (Cá nhân, 31358001, Q11) mở menu Thao tác → Xử lý hồ sơ của hồ sơ Chờ xem xét 2. Nhấn phím Tab liên tục | F23: Con trỏ di chuyển lần lượt: công tắc → ô chọn Ngày báo cáo → bảng → Hủy → Từ chối → Cập nhật | G23: Trung bình
A24: =IF(F24="","",ROW()-19-COUNTBLANK($F$20:F24)) -> 4 | B24: Kiểm tra thứ tự di chuyển con trỏ khi nhấn phím Shift+Tab | C24: Nhấn Shift+Tab liên tục từ control cuối cùng | E24: 1. Tại màn hình "Danh sách hồ sơ pháp lý" (Cá nhân, 31358001, Q11) mở menu Thao tác → Xử lý hồ sơ của hồ sơ Chờ xem xét 2. Focus control cuối cùng 3. Nhấn Shift+Tab liên tục | F24: Con trỏ di chuyển theo thứ tự ngược lại với phím Tab (từ dưới lên trên, từ phải sang trái) | G24: Trung bình
A25: =IF(F25="","",ROW()-19-COUNTBLANK($F$20:F25)) -> 5 | B25: Kiểm tra phím Enter | C25: Nhấn Enter khi đang focus control | E25: 1. Tại màn hình "Danh sách hồ sơ pháp lý" (Cá nhân, 31358001, Q11) mở menu Thao tác → Xử lý hồ sơ của hồ sơ Chờ xem xét 2. Focus control 3. Nhấn phím Enter | F25: Focus nút và nhấn Enter → thực hiện chức năng của nút | G25: Trung bình
A26: =IF(F26="","",ROW()-19-COUNTBLANK($F$20:F26)) -> 6 | B26: Kiểm tra tính năng responsive màn hình | C26: Thay đổi mức zoom bằng Ctrl+− / Ctrl+= | D26: Zoom 75%, 100%, 125%, 150% | E26: 1. Tại màn hình "Danh sách hồ sơ pháp lý" (Cá nhân, 31358001, Q11) mở menu Thao tác → Xử lý hồ sơ của hồ sơ Chờ xem xét 2. Nhấn Ctrl+− / Ctrl+= để đổi mức zoom | F26: Layout hiển thị hài hòa, không tràn khung, không vỡ giao diện ở mọi mức zoom | G26: Thấp
A27: =IF(F27="","",ROW()-19-COUNTBLANK($F$20:F27)) -> 7 | B27: Kiểm tra ngôn ngữ tiếng Việt chuẩn hành chính | C27: Rà toàn bộ nhãn, từ viết tắt trên màn hình | D27: Từ viết tắt: KH, TCTD, TTQT, QHTD, CIC, C06 | E27: 1. Tại màn hình "Danh sách hồ sơ pháp lý" (Cá nhân, 31358001, Q11) mở menu Thao tác → Xử lý hồ sơ của hồ sơ Chờ xem xét 2. Rà các nhãn, giá trị có từ viết tắt | F27: Không có từ viết tắt không được định nghĩa; từ viết tắt có tooltip giải thích (Quy tắc component) | G27: Thấp
A28: =IF(F28="","",ROW()-19-COUNTBLANK($F$20:F28)) | B28: Kiểm tra button chung trên màn hình
A29: =IF(F29="","",ROW()-19-COUNTBLANK($F$20:F29)) -> 8 | B29: Kiểm tra căn lề, chính tả label button | C29: Kiểm tra căn lề, chính tả label các button | E29: 1. Tại màn hình "Danh sách hồ sơ pháp lý" (Cá nhân, 31358001, Q11) mở menu Thao tác → Xử lý hồ sơ của hồ sơ Chờ xem xét 2. Quan sát các button: Hủy, Từ chối, Cập nhật | F29: Text căn giữa, chữ thường và chữ cái đầu in hoa, không lỗi chính tả | G29: Thấp
A30: =IF(F30="","",ROW()-19-COUNTBLANK($F$20:F30)) -> 9 | B30: Kiểm tra trạng thái enabled/disabled của các button theo điều kiện | C30: Kiểm tra trạng thái các button | E30: 1. Tại màn hình "Danh sách hồ sơ pháp lý" (Cá nhân, 31358001, Q11) mở menu Thao tác → Xử lý hồ sơ của hồ sơ Chờ xem xét 2. Quan sát trạng thái các button | F30: Hiển thị đúng trạng thái theo điều kiện SRS; chỉ có duy nhất 1 Primary button (Cập nhật) trong một khu vực | G30: Trung bình
A31: =IF(F31="","",ROW()-19-COUNTBLANK($F$20:F31)) -> 10 | B31: Kiểm tra click button thực hiện đúng chức năng | C31: Kiểm tra click các button | E31: 1. Tại màn hình "Danh sách hồ sơ pháp lý" (Cá nhân, 31358001, Q11) mở menu Thao tác → Xử lý hồ sơ của hồ sơ Chờ xem xét 2. Click lần lượt từng button | F31: Mỗi button thực hiện đúng chức năng mô tả trong SRS | G31: Cao
A32: =IF(F32="","",ROW()-19-COUNTBLANK($F$20:F32)) -> 11 | B32: Kiểm tra loading và disable button khi đang xử lý | C32: Kiểm tra button khi hệ thống đang xử lý | D32: Giả lập mạng chậm (DevTools: Slow 3G) | E32: 1. Tại màn hình "Danh sách hồ sơ pháp lý" (Cá nhân, 31358001, Q11) mở menu Thao tác → Xử lý hồ sơ của hồ sơ Chờ xem xét 2. Click button gọi API 3. Click tiếp nhiều lần khi đang xử lý | F32: Button hiển thị loading spinner và bị disable; thao tác chỉ được thực hiện 1 lần | G32: Cao
A33: =IF(F33="","",ROW()-19-COUNTBLANK($F$20:F33)) -> 12 | B33: Kiểm tra giữ bộ lọc sau khi F5 hoặc chuyển trang | C33: Kiểm tra giữ tùy chọn bộ lọc và cấu hình hiển thị | E33: 1. Tại màn hình "Danh sách hồ sơ pháp lý" (Cá nhân, 31358001, Q11) mở menu Thao tác → Xử lý hồ sơ của hồ sơ Chờ xem xét 2. Chọn điều kiện, Tìm kiếm 3. Nhấn F5 hoặc chuyển sang chức năng khác rồi quay lại | F33: Hệ thống giữ tùy chọn bộ lọc và cấu hình hiển thị đã chọn trước đó (không lưu giá trị) — Quy tắc component | G33: Trung bình
A34: =IF(F34="","",ROW()-19-COUNTBLANK($F$20:F34)) | B34: Kiểm tra title Xử lý hồ sơ pháp lý
A35: =IF(F35="","",ROW()-19-COUNTBLANK($F$20:F35)) -> 13 | B35: Kiểm tra hiển thị title | C35: Kiểm tra hiển thị title | E35: 1. Tại màn hình "Danh sách hồ sơ pháp lý" (Cá nhân, 31358001, Q11) mở menu Thao tác → Xử lý hồ sơ của hồ sơ Chờ xem xét 2. Kiểm tra hiển thị title | F35: Title cố định mặc định: "Xử lý hồ sơ pháp lý" | G35: Thấp
A36: =IF(F36="","",ROW()-19-COUNTBLANK($F$20:F36)) -> 14 | B36: Kiểm tra chỉnh sửa title | C36: Kiểm tra chỉnh sửa title | E36: 1. Tại màn hình "Danh sách hồ sơ pháp lý" (Cá nhân, 31358001, Q11) mở menu Thao tác → Xử lý hồ sơ của hồ sơ Chờ xem xét 2. Click / thử nhập vào title | F36: Không cho phép chỉnh sửa | G36: Thấp
A37: =IF(F37="","",ROW()-19-COUNTBLANK($F$20:F37)) | B37: Kiểm tra thẻ hồ sơ đang xem xét
A38: =IF(F38="","",ROW()-19-COUNTBLANK($F$20:F38)) -> 15 | B38: Kiểm tra hiển thị tên khách hàng | C38: Hiển thị Tên khách hàng | E38: 1. Tại màn hình "Danh sách hồ sơ pháp lý" (Cá nhân, 31358001, Q11) mở menu Thao tác → Xử lý hồ sơ của hồ sơ Chờ xem xét 2. Quan sát Tên khách hàng | F38: Hiển thị TTC04 của hồ sơ đang xem xét; chỉ đọc | G38: Trung bình
A39: =IF(F39="","",ROW()-19-COUNTBLANK($F$20:F39)) -> 16 | B39: Kiểm tra hiển thị mã khách hàng | C39: Hiển thị Mã khách hàng | E39: 1. Tại màn hình "Danh sách hồ sơ pháp lý" (Cá nhân, 31358001, Q11) mở menu Thao tác → Xử lý hồ sơ của hồ sơ Chờ xem xét 2. Quan sát Mã khách hàng | F39: Hiển thị TTC03, cùng dòng với Mã CIC ở thẻ phải (BR-047); chỉ đọc | G39: Trung bình
A40: =IF(F40="","",ROW()-19-COUNTBLANK($F$20:F40)) -> 17 | B40: Kiểm tra hiển thị loại khách hàng | C40: Hiển thị Loại khách hàng | E40: 1. Tại màn hình "Danh sách hồ sơ pháp lý" (Cá nhân, 31358001, Q11) mở menu Thao tác → Xử lý hồ sơ của hồ sơ Chờ xem xét 2. Quan sát Loại khách hàng | F40: Hiển thị TTC05; chỉ đọc | G40: Trung bình
A41: =IF(F41="","",ROW()-19-COUNTBLANK($F$20:F41)) -> 18 | B41: Kiểm tra hiển thị đầu mối báo cáo | C41: Hiển thị Đầu mối báo cáo | E41: 1. Tại màn hình "Danh sách hồ sơ pháp lý" (Cá nhân, 31358001, Q11) mở menu Thao tác → Xử lý hồ sơ của hồ sơ Chờ xem xét 2. Quan sát Đầu mối báo cáo | F41: Hiển thị TTC00 dạng mã - tên; chỉ đọc | G41: Trung bình
A42: =IF(F42="","",ROW()-19-COUNTBLANK($F$20:F42)) -> 19 | B42: Kiểm tra hiển thị ngày báo cáo | C42: Hiển thị Ngày báo cáo | E42: 1. Tại màn hình "Danh sách hồ sơ pháp lý" (Cá nhân, 31358001, Q11) mở menu Thao tác → Xử lý hồ sơ của hồ sơ Chờ xem xét 2. Quan sát Ngày báo cáo | F42: Hiển thị KB001, DD/MM/YYYY; chỉ đọc | G42: Trung bình
A43: =IF(F43="","",ROW()-19-COUNTBLANK($F$20:F43)) -> 20 | B43: Kiểm tra hiển thị trạng thái | C43: Hiển thị Trạng thái | E43: 1. Tại màn hình "Danh sách hồ sơ pháp lý" (Cá nhân, 31358001, Q11) mở menu Thao tác → Xử lý hồ sơ của hồ sơ Chờ xem xét 2. Quan sát Trạng thái | F43: Hiển thị Badge "Chờ xem xét" màu cam; chỉ đọc | G43: Trung bình
A44: =IF(F44="","",ROW()-19-COUNTBLANK($F$20:F44)) | B44: Kiểm tra thẻ Hồ sơ tại CIC
A45: =IF(F45="","",ROW()-19-COUNTBLANK($F$20:F45)) -> 21 | B45: Kiểm tra hiển thị mã CIC | C45: Mã CIC chỉ xem | E45: 1. Tại màn hình "Danh sách hồ sơ pháp lý" (Cá nhân, 31358001, Q11) mở menu Thao tác → Xử lý hồ sơ của hồ sơ Chờ xem xét 2. Quan sát Mã CIC 3. Thử click / sửa Mã CIC | F45: Hiển thị Mã CIC của KH, không chọn được mã khác (mục 7 bảng thành phần của popup "Xử lý hồ sơ pháp lý tệp D10/D11") | G45: Cao
...

Sheet M7_XuLyDongThoi
B1: KỊCH BẢN KIỂM THỬ CHỨC NĂNG
B3: Tên màn hình/Tên chức năng | C3: Màn hình "Xử lý đồng thời hồ sơ pháp lý" D10/D11 và Q11 + popup "Xác nhận cập nhật thông tin hồ sơ"/popup "Xác nhận từ chối cập nhật thông tin hồ sơ" (FEAT-XLDL-009-06, 07) | E3: KBNV
B4: Mã trường hợp kiểm thử | C4: HSPL | E4: TKCT
B6: Manual test
B7: Số trường hợp kiểm thử đạt (P) | C7: =COUNTIF($O$20:$O$339,"P") -> 0
B8: Số trường hợp kiểm thử không đạt (F) | C8: =COUNTIF($O$20:$O$339,"F") -> 0
B9: Số trường hợp kiểm thử đang xem xét (PE) | C9: =COUNTIF($O$20:$O$339,"PE") -> 0
B10: Số trường hợp kiểm thử chưa thực hiện | C10: =C11-C7-C8-C9 -> 284
B11: Tổng số trường hợp kiểm thử | C11: =COUNTA($F$20:$F$339) -> 284
A15: ID | B15: Mục đích kiểm thử | C15: Trường hợp kiểm thử | D15: Data test | E15: Các bước thực hiện | F15: Kết quả mong muốn | G15: Mức độ nghiêm trọng | H15: Hình ảnh | I15: Manual Test | O15: Kết quả test (M) | P15: Mã lỗi | Q15: Ghi chú
I16: WEB
I17: Lần 1 | J17: Ngày thực hiện | K17: Lần 2 | L17: Ngày thực hiện | M17: Lần 3 | N17: Ngày thực hiện
B18: Pre-condition: - Đăng nhập tài khoản cbxl01 (ROLE-CBTTXLDL, phân quyền TCTD 31358001 và 79202501) - Menu: Thu thập và xử lý dữ liệu > Xử lý dữ liệu > Hồ sơ pháp lý - Kho tiền dữ liệu có hồ sơ pháp lý hợp lệ tệp D10, D11, Q11 của cả KH Cá nhân và Tổ chức, ở đủ 4 trạng thái Chờ cấp mã / Chờ xem xét / Đã xử lý / Từ chối - Có hồ sơ Chờ xem xét của 31358001 có ≥ 3 phiên bản tại kho TCTD cùng Mã CIC và đầu mối; KH có hồ sơ tại CIC (có/không cờ C06) - Danh mục chỉ tiêu đánh dấu quan trọng: TTC04, CN001, CN005, CN006, CN008, CN010, CN016, TC004–TC006, TC011 - Tài khoản cbxl02 (ROLE-CBTTXLDL, phân quyền TCTD 31358001) để kiểm tra xử lý đồng thời giữa 2 cán bộ
B19: Giao diện (Phần này viết các trường hợp kiểm thử cho giao diện chung và các giao diện cho các control)
A20: =IF(F20="","",ROW()-19-COUNTBLANK($F$20:F20)) | B20: Kiểm tra giao diện chung
